<?xml version="1.0" encoding="utf-8"?>
<!-- =================================================================================== -->
<!-- |    This document was autogenerated by xacro from c_crane.urdf.xacro             | -->
<!-- |    EDITING THIS FILE BY HAND IS NOT RECOMMENDED                                 | -->
<!-- =================================================================================== -->
<robot name="c_crane" xmlns:xacro="http://www.ros.org/wiki/xacro">
  <!-- color of robot. important-->
  <material name="white">
    <color rgba="1 1 1 1"/>
  </material>
  <material name="blue">
    <color rgba="0 0 1 1"/>
  </material>
  <material name="red">
    <color rgba="1 0 0 1"/>
  </material>
  <material name="green">
    <color rgba="0 1 0 1"/>
  </material>
  <!-- base_link -->
  <link name="base_link"/>
  <!-- lower link -->
  <link name="lower_link">
    <visual>
      <origin rpy="0 0 0" xyz="0 0 0"/>
      <geometry>
        <mesh filename="package://c_crane_description/meshes/lower.stl"/>
      </geometry>
    </visual>
    <collision>
      <origin rpy="0 0 0" xyz="0 0 0"/>
      <geometry>
        <mesh filename="package://c_crane_description/meshes/lower.stl"/>
      </geometry>
    </collision>
    <inertial>
      <inertia ixx="52818.8409" ixy="10" ixz="10" iyy="567.18712194" iyz="10" izz="277498.56657"/>
      <origin rpy="0 0 0" xyz="-0.124 0.001 -0.65"/>
      <geometry>
        <mesh filename="package://c_crane_description/meshes/lower.stl"/>
      </geometry>
      <mass value="43532.456"/>
    </inertial>
  </link>
  <joint name="body_joint" type="fixed">
    <origin rpy="0 0 0" xyz="0 0 0"/>
    <parent link="base_link"/>
    <child link="lower_link"/>
  </joint>
  <!-- upper link -->
  <link name="upper_link">
    <visual>
      <origin rpy="0 0 0" xyz="0 0 0"/>
      <geometry>
        <mesh filename="package://c_crane_description/meshes/upper.stl"/>
      </geometry>
    </visual>
    <collision>
      <origin rpy="0 0 0" xyz="0 0 0"/>
      <geometry>
        <mesh filename="package://c_crane_description/meshes/upper.stl"/>
      </geometry>
    </collision>
    <inertial>
      <inertia ixx="1603823" ixy="10" ixz="10" iyy="23427" iyz="10" izz="560938"/>
      <origin rpy="0 0 0" xyz="-2.887 -0.042, 1.010"/>
      <geometry>
        <mesh filename="package://c_crane_description/meshes/upper.stl"/>
      </geometry>
      <mass value="56650"/>
    </inertial>
  </link>
  <joint name="yaw_joint" type="revolute">
    <origin rpy="0 0 0" xyz="0 0 0"/>
    <parent link="lower_link"/>
    <child link="upper_link"/>
    <axis xyz="0 0 1"/>
    <limit effort="10000000" lower="-1.57" upper="1.57" velocity="10000"/>
  </joint>
  <transmission name="yaw_joint_trans">
    <type>transimission_interface/SimpleTransmission</type>
    <joint name="yaw_joint">
      <hardwareInterface>hardware_interface/EffortJointInterface</hardwareInterface>
    </joint>
    <actuator name="yaw_joint_motor">
      <hardwareInterface>hardware_interface/EffortJointInterface</hardwareInterface>
      <mechanicalReduction>1</mechanicalReduction>
    </actuator>
  </transmission>
  <link name="boom_link">
    <visual>
      <geometry>
        <mesh filename="package://c_crane_description/meshes/boom.stl"/>
      </geometry>
      <origin rpy="0 0 0" xyz="-1.1 0 -0.87"/>
    </visual>
    <collision>
      <geometry>
        <mesh filename="package://c_crane_description/meshes/boom.stl"/>
      </geometry>
      <origin rpy="0 0 0" xyz="-1.1 0 -0.87"/>
    </collision>
    <inertial>
      <inertia ixx="309720" ixy="10" ixz="184495" iyy="420788" iyz="10" izz="113315"/>
      <!--origin xyz="-1.1 0 -0.87" rpy="0 0 0"/-->
      <origin rpy="0 0 0" xyz="8.8153 0.1832 14.276"/>
      <geometry>
        <mesh filename="package://c_crane_description/meshes/boom.stl"/>
      </geometry>
      <mass value="5618"/>
    </inertial>
  </link>
  <joint name="pitch_joint" type="revolute">
    <origin rpy="0 0 0" xyz="1.1 0 0.87"/>
    <parent link="upper_link"/>
    <child link="boom_link"/>
    <axis xyz="0 1 0"/>
    <limit effort="10000000" lower="-1.57" upper="1.57" velocity="10000"/>
  </joint>
  <transmission name="pitch_joint_trans">
    <type>transimission_interface/SimpleTransmission</type>
    <joint name="pitch_joint">
      <hardwareInterface>hardware_interface/EffortJointInterface</hardwareInterface>
    </joint>
    <actuator name="pitch_joint_motor">
      <hardwareInterface>hardware_interface/EffortJointInterface</hardwareInterface>
      <mechanicalReduction>1</mechanicalReduction>
    </actuator>
  </transmission>
  <!--
	<link name="rope_link">
		<visual>
			<xacro:default_mesh name="rope"/>
			<origin xyz="0 0 0" rpy="-1.57 0 0"/>
			<material name="green"/>
		</visual>
		<collision>
			<xacro:default_mesh name="rope"/>
			<origin xyz="0 0 0" rpy="-1.57 0 0"/>
		</collision>
		<inertial>
			<xacro:default_inertial/>
			<origin xyz="0 0 0" rpy="-1.57 0 0"/>
			<xacro:default_mesh name="rope"/>
			<mass value="100"/>
		</inertial>
	</link>
	-->
  <!--
	<link name="payload_link">
		<visual>
			<xacro:default_mesh name="payload"/>
			<origin xyz="0 0 0" rpy="0 0 0"/>
			<material name="green"/>
		</visual>
		<collision>
			<xacro:default_mesh name="payload"/>
			<origin xyz="0 0 0" rpy="0 0 0"/>
		</collision>
		<inertial>
			<xacro:default_inertial/>
			<origin xyz="0 0 0" rpy="0 0 0"/>
			<xacro:default_mesh name="payload"/>
			<mass value="100"/>
		</inertial>
	</link>
	-->
  <!--
	<link name="ball_joint_x_link"/>

	<joint name="ball_x_joint" type="revolute">
		<origin xyz="14.13 0.2 22.6" rpy="0 0 0"/>
		<parent link="boom_link"/>
		<child  link="ball_joint_x_link"/>
		<axis xyz="1 0 0"/>
		<limit lower="-1.57" upper="1.57" effort="0" velocity="0"/>
		<dynamics damping="0.005"/>
	</joint>

	<link name="ball_joint_y_link"/>

	<joint name="ball_y_joint" type="revolute">
		<parent link="ball_joint_x_link"/>
		<child  link="ball_joint_y_link"/>
		<axis xyz="0 1 0"/>
		<limit lower="-1.57" upper="1.57" effort="0" velocity="0"/>
		<dynamics damping="0.005"/>
	</joint>

	<joint name="ball_z_joint" type="revolute">
		<parent link="ball_joint_y_link"/>
		<child  link="rope_link"/>
		<axis xyz="0 0 1"/>
		<limit lower="-1.57" upper="1.57" effort="0" velocity="0"/>
		<dynamics damping="0.005"/>
	</joint>

	<joint name="payload_joint" type="fixed">
		<origin xyz="-0.5 -0.5 -20.5" rpy="0 0 0"/>
		<parent link="rope_link"/>
		<child  link="payload_link"/>
	</joint>
	-->
  <!-- link fixed in order to stand rigidly in gazebo -->
  <link name="world"/>
  <joint name="fixed" type="fixed">
    <parent link="world"/>
    <child link="base_link"/>
  </joint>
  <!-- ros_control -->
  <gazebo>
    <plugin filename="libgazebo_ros_control.so" name="gazebo_ros_control">
      <robotNamespace>/c_crane</robotNamespace>
    </plugin>
    <mu1>0.1</mu1>
    <mu2>0.1</mu2>
  </gazebo>
</robot>

