<?xml version="1.0"?>
<!-- frame_id: "front_laser_link" -->
<robot name="k_crane" xmlns:xacro="http://ros.org/wiki/xacro">
  <xacro:macro name="laser_move_macro" params="parent prefix xyz rpy"> 


    <!--
    <joint name="base_to_laser_joint" type="fixed">
      <parent link="${parent}"/>
      <child  link="${prefix}"/>
      <origin xyz="${xyz}" rpy="${rpy}"/> 
    </joint>
    -->

    <joint name="base_to_laser_joint" type="continuous">
      <parent link="${parent}"/>
      <child  link="${prefix}_link"/>
      <origin xyz="${xyz}" rpy="${rpy}"/> 
      <axis xyz="1 0 0"/>
      <limit effort="10000" velocity="1000"/>
      <joint_properties damping="1.0" friction="15.0"/>

    </joint>

    
     <!-- ROS Control plugin for Gazebo --> 
    <gazebo>
        <plugin name="gazebo_ros_control" filename="libgazebo_ros_control.so">
          <robotNamespace>/marvin</robotNamespace>
          <robotSimType>gazebo_ros_control/DefaultRobotHWSim</robotSimType>
          <legacyModeNS>true</legacyModeNS>
        </plugin>
    </gazebo>

    <transmission name="base_to_laser_trans">
        <type>transmission_interface/SimpleTransmission</type>
        <actuator name="motor1">
            <mechanicalReduction>1</mechanicalReduction>
        </actuator>
        <joint name="base_to_laser_joint">
            <hardwareInterface>hardware_interface/EffortJointInterface</hardwareInterface>
        </joint>
   </transmission>
   
      

    <link name="${prefix}_link">
      <inertial>
			  <origin xyz="0 0 1" rpy="0 0 0"/>
        <mass value="1.0"/>
        <inertia ixx="0.001" ixy="0.0" ixz="0.0" iyy="0.001" iyz="0.0" izz="0.001"/>
      </inertial>

      <visual>
			  <origin xyz="0 0 1" rpy="0 0 0"/>
        <geometry>
          <cylinder radius="0.2" length="0.6" />
        </geometry>
        <material name="red" />
      </visual>
      <collision>
			  <origin xyz="0 0 1" rpy="0 0 0"/>
        <geometry>
          <cylinder radius="0.2" length="0.6" />
        </geometry>
      </collision>
    </link>
    <gazebo reference="${prefix}_link">
      <material>Gazebo/Red</material>
      <sensor type="ray" name="${prefix}">
        <pose>0 0 0 0 0 0</pose>
        <visualize>true</visualize>
        <update_rate>30</update_rate>
        <ray>
          <scan>
            <horizontal>
              <samples>1441</samples>
              <resolution>1</resolution>
              <min_angle>${radians(-180)}</min_angle>
              <max_angle>${radians( 180)}</max_angle>
            </horizontal>
          </scan>
          <range>
            <min>5.0</min>
            <max>250.0</max>
            <resolution>0.01</resolution>
          </range>
          <noise>
            <type>gaussian</type>
            <mean>0.0</mean>
            <stddev>0.01</stddev>
          </noise>
        </ray>
        <plugin name="gazebo_ros_lidar_controller" filename="libgazebo_ros_laser.so">
          <topicName>/${prefix}_link/scan</topicName>
          <frameName>${prefix}_link</frameName>
        </plugin>
      </sensor>
    </gazebo>





    <joint name="laser_to_imu_joint" type="fixed">
		<parent link="${prefix}_link"/>
		<child  link="imu_hook_link"/>
    <origin xyz="0.5 0 0" rpy=" 0 ${radians(90)} ${radians(0)}"/> 
		</joint>

		<link name="imu_hook_link">
			  <origin xyz="0 0 1" rpy="0 0 0"/>
			<visual>
			  <origin xyz="0 0 1" rpy="0 0 0"/>
				<geometry>
					<box size="0.458 0.7 0.94"/>
				</geometry>
			</visual>
			<inertial>
				<geometry>
					<box size="0.458 0.7 0.94"/>
				</geometry>
				<mass value="0.5"/>
				<inertia
					ixx="0.001"
					ixy="0.001"
					ixz="0.001"
					iyy="0.001"
					iyz="0.001"
					izz="0.001"/>
			</inertial>
			<collision>
				<geometry>
					<box size="0.458 0.7 0.94"/>
				</geometry>
			</collision>
		</link>

		<gazebo reference="imu_hook_link">
		<material>Gazebo/Red</material>
		<gravity>true</gravity>
		<sensor name="imu_sensor" type="imu">
			<always_on>true</always_on>
			<update_rate>128</update_rate>
			<visualize>true</visualize>
			<topic>data</topic>
			<plugin filename="libgazebo_ros_imu_sensor.so" name="imu_plugin">
			<topicName>imu_hook_link/data</topicName>
			<bodyName>imu_hook_link</bodyName>
			<updateRateHZ>128</updateRateHZ>
			<gaussianNoise>0.0</gaussianNoise>
			<xyzOffset>0 0 0</xyzOffset>
			<rpyOffset>0 0 0</rpyOffset>
			<frameName>imu_hook_link</frameName>
			</plugin>
			<pose>0 0 0 0 0 0</pose>
		</sensor>
		</gazebo>


  </xacro:macro> 
</robot>
