<?xml version="1.0"?>
<!-- frame_id: "front_laser_link" -->
<robot name="k_crane" xmlns:xacro="http://ros.org/wiki/xacro">
  <xacro:macro name="laser_move_macro" params="parent prefix xyz rpy"> 


    <!--
    <joint name="base_to_laser_joint" type="fixed">
      <parent link="${parent}"/>
      <child  link="${prefix}"/>
      <origin xyz="${xyz}" rpy="${rpy}"/> 
    </joint>
    -->

    <joint name="base_to_laser_joint" type="continuous">
      <parent link="${parent}"/>
      <child  link="${prefix}_link"/>
      <origin xyz="${xyz}" rpy="${rpy}"/> 
      <axis xyz="1 0 0"/>
      <limit effort="10000" velocity="1000"/>
      <joint_properties damping="1.0" friction="15.0"/>
    </joint>

    
     <!-- ROS Control plugin for Gazebo --> 
    <gazebo>
        <plugin name="gazebo_ros_control" filename="libgazebo_ros_control.so">
          <robotNamespace>/marvin</robotNamespace>
          <robotSimType>gazebo_ros_control/DefaultRobotHWSim</robotSimType>
          <legacyModeNS>true</legacyModeNS>
        </plugin>
    </gazebo>

    <transmission name="base_to_laser_trans">
        <type>transmission_interface/SimpleTransmission</type>
        <actuator name="motor1">
            <mechanicalReduction>1</mechanicalReduction>
        </actuator>
        <joint name="base_to_laser_joint">
            <hardwareInterface>hardware_interface/EffortJointInterface</hardwareInterface>
        </joint>
   </transmission>
   
      

    <link name="${prefix}_link">

     <visual>
			  <!-- <origin xyz="0 0 1" rpy="0 0 0"/> -->
			  <origin xyz="0 0 0" rpy="0 0 0"/>
        <geometry>
          <!-- <cylinder radius="0.2" length="0.6" /> -->
          <box size="0.2 0.15 0.1"/>
        </geometry>
        <material name="Blue" />
     </visual>

      <inertial>
			  <!-- <origin xyz="0 0 1" rpy="0 0 0"/> -->
			  <origin xyz="0 0 1" rpy="0 0 0"/>
        <mass value="1.0"/>
        <inertia ixx="0.001" ixy="0.0" ixz="0.0" iyy="0.001" iyz="0.0" izz="0.001"/>
      </inertial>

      <collision>
			  <!-- <origin xyz="0 0 1" rpy="0 0 0"/> -->
			  <origin xyz="0 0 0" rpy="0 0 0"/>
        <geometry>
          <cylinder radius="0.2" length="0.6" />
        </geometry>
      </collision>
    </link>
    <gazebo reference="${prefix}_link">
      <material>Gazebo/Red</material>
      <sensor type="ray" name="${prefix}">
        <pose>0 0 0 0 0 0</pose>
        <visualize>true</visualize>
        <update_rate>5</update_rate>
       
        <ray>
          <scan>
            <horizontal>
              <samples>1441</samples>
              <resolution>1</resolution>
              <min_angle>${radians(-180)}</min_angle>
              <max_angle>${radians( 180)}</max_angle>
            </horizontal>
          </scan>
          <range>
            <min>10.0</min>
            <max>200.0</max>
            <resolution>0.01</resolution>
          </range>
          <noise>
            <type>gaussian</type>
            <mean>0.0</mean>
            <stddev>0.01</stddev>
          </noise>
        </ray>
        <plugin name="gazebo_ros_lidar_controller" filename="libgazebo_ros_laser.so">
          <topicName>/${prefix}_link/scan</topicName>
          <frameName>${prefix}_link</frameName>
        </plugin>
      </sensor>
    </gazebo>





  </xacro:macro> 
</robot>
