<?xml version="1.0" encoding="utf-8"?>
<!-- =================================================================================== -->
<!-- |    This document was autogenerated by xacro from c_crane_with_payload.urdf.xacro | -->
<!-- |    EDITING THIS FILE BY HAND IS NOT RECOMMENDED                                 | -->
<!-- =================================================================================== -->
<robot name="c_crane" xmlns:xacro="http://www.ros.org/wiki/xacro">
  <!-- color of robot. important-->
  <material name="white">
    <color rgba="1 1 1 1"/>
  </material>
  <material name="blue">
    <color rgba="0 0 1 1"/>
  </material>
  <material name="red">
    <color rgba="1 0 0 1"/>
  </material>
  <material name="green">
    <color rgba="0 1 0 1"/>
  </material>
  <gazebo>
    <plugin filename="libgazebo_ros_control.so" name="gazebo_ros_control">
      <robotNamespace>/c_crane</robotNamespace>
      <robotSimType>gazebo_ros_control/DefaultRobotHWSim</robotSimType>
    </plugin>
  </gazebo>
  <!-- base_link -->
  <link name="base_link"/>
  <!-- lower link -->
  <link name="lower_link">
    <visual>
      <origin rpy="0 0 0" xyz="0 0 0"/>
      <geometry>
        <mesh filename="package://c_crane_description/meshes/lower.stl"/>
      </geometry>
    </visual>
    <collision>
      <origin rpy="0 0 0" xyz="0 0 0"/>
      <geometry>
        <mesh filename="package://c_crane_description/meshes/lower.stl"/>
      </geometry>
    </collision>
    <inertial>
      <inertia ixx="23141.64" ixy="0.54" ixz="4395.71" iyy="24360.18" iyz="5.63" izz="1218.63"/>
      <origin rpy="0 0 0" xyz="-0.1346 0.0 -0.7573"/>
      <geometry>
        <mesh filename="package://c_crane_description/meshes/lower.stl"/>
      </geometry>
      <mass value="38882"/>
    </inertial>
  </link>
  <joint name="body_joint" type="fixed">
    <origin rpy="0 0 0" xyz="0 0 1.5"/>
    <parent link="base_link"/>
    <child link="lower_link"/>
  </joint>
  <!-- upper link -->
  <link name="upper_link">
    <visual>
      <origin rpy="0 0 0" xyz="0 0 0"/>
      <geometry>
        <mesh filename="package://c_crane_description/meshes/upper.stl"/>
      </geometry>
    </visual>
    <collision>
      <origin rpy="0 0 0" xyz="0 0 0"/>
      <geometry>
        <mesh filename="package://c_crane_description/meshes/upper.stl"/>
      </geometry>
    </collision>
    <inertial>
      <inertia ixx="101881.52" ixy="-50965.14" ixz="-273528.32" iyy="1007600.56" iyz="12056.92" izz="910589.22"/>
      <origin rpy="0 0 0" xyz="-3.1369 0.1401 1.1322"/>
      <geometry>
        <mesh filename="package://c_crane_description/meshes/upper.stl"/>
      </geometry>
      <mass value="77333"/>
    </inertial>
  </link>
  <joint name="yaw_joint" type="revolute">
    <origin rpy="0 0 0" xyz="0 0 0"/>
    <parent link="lower_link"/>
    <child link="upper_link"/>
    <axis xyz="0 0 1"/>
    <friction frinction="0.05"/>
    <limit effort="100000000" lower="-1.57" upper="1.57" velocity="10000"/>
  </joint>
  <transmission name="yaw_joint_trans">
    <type>transimission_interface/SimpleTransmission</type>
    <joint name="yaw_joint">
      <hardwareInterface>hardware_interface/VelocityJointInterface</hardwareInterface>
    </joint>
    <actuator name="yaw_joint_motor">
      <hardwareInterface>hardware_interface/VelocityJointInterface</hardwareInterface>
      <mechanicalReduction>100</mechanicalReduction>
    </actuator>
  </transmission>
  <link name="boom_link">
    <visual>
      <geometry>
        <mesh filename="package://c_crane_description/meshes/boom.stl"/>
      </geometry>
      <!--origin xyz="-1.4 -0.191 -1.008 " rpy="0 0 0"/-->
      <origin rpy="0 0 -1.57" xyz="0 0 0"/>
    </visual>
    <collision>
      <geometry>
        <mesh filename="package://c_crane_description/meshes/boom.stl"/>
      </geometry>
      <!--origin xyz="-1.4 -0.191 -1.008 " rpy="0 0 0"/-->
      <origin rpy="0 0 -1.57" xyz="0 0 0"/>
    </collision>
    <inertial>
      <inertia ixx="3398809.65" ixy="-2996.64" ixz="18.45" iyy="7038.42" iyz="8974.74" izz="3398634.48"/>
      <origin rpy="0 0 0" xyz="0 0 0"/>
      <geometry>
        <mesh filename="package://c_crane_description/meshes/boom.stl"/>
      </geometry>
      <mass value="8243"/>
    </inertial>
  </link>
  <joint name="pitch_joint" type="revolute">
    <origin rpy="0 0 0" xyz="1.4 0.191 1.008 "/>
    <parent link="upper_link"/>
    <child link="boom_link"/>
    <axis xyz="0 1 0"/>
    <friction frinction="0.05"/>
    <limit effort="100000000" lower="-1.57" upper="0" velocity="10000"/>
  </joint>
  <transmission name="pitch_joint_trans">
    <type>transimission_interface/SimpleTransmission</type>
    <joint name="pitch_joint">
      <hardwareInterface>hardware_interface/VelocityJointInterface</hardwareInterface>
    </joint>
    <actuator name="pitch_joint_motor">
      <hardwareInterface>hardware_interface/VelocityJointInterface</hardwareInterface>
      <mechanicalReduction>100</mechanicalReduction>
    </actuator>
  </transmission>
  <!-- link fixed in order to stand rigidly in gazebo -->
  <link name="world"/>
  <joint name="fixed" type="fixed">
    <parent link="world"/>
    <child link="base_link"/>
    <origin rpy="0 0 0" xyz="0 0 0"/>
  </joint>
  <link name="rope1_link">
    <origin rpy="0 1.57079632679 0" xyz="0 0 0"/>
    <inertial>
      <origin rpy="0 1.57079632679 0" xyz="0 0 0"/>
      <geometry>
        <cylinder length="0.1" radius="0.05"/>
      </geometry>
      <mass value="0.1"/>
      <inertia ixx="0.001" ixy="0.001" ixz="0.001" iyy="0.001" iyz="0.001" izz="0.001"/>
    </inertial>
    <visual>
      <origin rpy="0 1.57079632679 0" xyz="0 0 0"/>
      <geometry>
        <cylinder length="0.1" radius="0.05"/>
      </geometry>
    </visual>
    <collision>
      <origin rpy="0 1.57079632679 0" xyz="0 0 0"/>
      <geometry>
        <cylinder length="0.1" radius="0.05"/>
      </geometry>
    </collision>
  </link>
  <link name="rope2_link">
    <origin rpy="$0 0 0" xyz="0 0 0"/>
    <inertial>
      <origin rpy="1.57079632679 0 0" xyz="0 0 0"/>
      <geometry>
        <cylinder length="0.1" radius="0.05"/>
      </geometry>
      <mass value="0.1"/>
      <inertia ixx="0.001" ixy="0.001" ixz="0.001" iyy="0.001" iyz="0.001" izz="0.001"/>
    </inertial>
    <visual>
      <origin rpy="1.57079632679 0 0" xyz="0 0 0"/>
      <geometry>
        <cylinder length="0.1" radius="0.05"/>
      </geometry>
    </visual>
    <collision>
      <origin rpy="1.57079632679 0 0" xyz="0 0 0"/>
      <geometry>
        <cylinder length="0.1" radius="0.05"/>
      </geometry>
    </collision>
  </link>
  <joint name="joint12" type="revolute">
    <parent link="rope1_link"/>
    <child link="rope2_link"/>
    <origin rpy="0 0 0" xyz="0 0 -0.1"/>
    <axis xyz="0 1 0"/>
    <limit effort="0" lower="-1.57079632679" upper="1.57079632679" velocity="100"/>
  </joint>
  <link name="rope3_link">
    <origin rpy="0 0 0" xyz="0 0 0"/>
    <inertial>
      <geometry>
        <cylinder length="0.1" radius="0.05"/>
      </geometry>
      <mass value="0.1"/>
      <inertia ixx="0.001" ixy="0.001" ixz="0.001" iyy="0.001" iyz="0.001" izz="0.001"/>
    </inertial>
    <visual>
      <geometry>
        <cylinder length="0.1" radius="0.05"/>
      </geometry>
    </visual>
    <collision>
      <geometry>
        <cylinder length="0.1" radius="0.05"/>
      </geometry>
    </collision>
  </link>
  <joint name="joint23" type="revolute">
    <parent link="rope2_link"/>
    <child link="rope3_link"/>
    <origin rpy="0 0 0" xyz="0 0 -0.1"/>
    <axis xyz="0 0 1"/>
    <limit effort="0" lower="-1.57079632679" upper="1.57079632679" velocity="100"/>
  </joint>
  <link name="rope4_link">
    <origin rpy="0 0 0" xyz="0 0 0"/>
    <inertial>
      <geometry>
        <cylinder length="7" radius="0.05"/>
      </geometry>
      <mass value="0.1"/>
      <inertia ixx="0.001" ixy="0.001" ixz="0.001" iyy="0.001" iyz="0.001" izz="0.001"/>
    </inertial>
    <visual>
      <geometry>
        <cylinder length="7" radius="0.05"/>
      </geometry>
    </visual>
    <collision>
      <geometry>
        <cylinder length="7" radius="0.05"/>
      </geometry>
    </collision>
  </link>
  <joint name="joint34" type="fixed">
    <parent link="rope3_link"/>
    <child link="rope4_link"/>
    <origin rpy="0 0 0" xyz="0 0 -3.5"/>
    <axis xyz="0 0 1"/>
    <limit effort="0" lower="-1.57079632679" upper="1.57079632679" velocity="100"/>
  </joint>
  <joint name="joint_bool1" type="revolute">
    <parent link="upper_link"/>
    <child link="rope1_link"/>
    <limit effort="100" lower="-1.57079632679" upper="1.57079632679" velocity="100"/>
    <origin rpy="0 0 0" xyz="17.365 -0.0017, 27.244"/>
    <axis xyz="1 0 0"/>
  </joint>
</robot>

