<?xml version="1.0" encoding="utf-8"?>
<!-- =================================================================================== -->
<!-- |    This document was autogenerated by xacro from c_crane_no_load.urdf.xacro     | -->
<!-- |    EDITING THIS FILE BY HAND IS NOT RECOMMENDED                                 | -->
<!-- =================================================================================== -->
<robot name="c_crane" xmlns:xacro="http://www.ros.org/wiki/xacro">
  <!-- color of robot. important-->
  <material name="white">
    <color rgba="1 1 1 1"/>
  </material>
  <material name="blue">
    <color rgba="0 0 1 1"/>
  </material>
  <material name="red">
    <color rgba="1 0 0 1"/>
  </material>
  <material name="green">
    <color rgba="0 1 0 1"/>
  </material>
  <gazebo>
    <plugin filename="libgazebo_ros_control.so" name="gazebo_ros_control">
      <robotNamespace>/c_crane</robotNamespace>
      <robotSimType>gazebo_ros_control/DefaultRobotHWSim</robotSimType>
    </plugin>
  </gazebo>
  <!-- base_link -->
  <link name="base_link"/>
  <!-- lower link -->
  <link name="lower_link">
    <visual>
      <origin rpy="0 0 0" xyz="0 0 0"/>
      <geometry>
        <mesh filename="package://c_crane_description/meshes/lower.stl"/>
      </geometry>
    </visual>
    <collision>
      <origin rpy="0 0 0" xyz="0 0 0"/>
      <geometry>
        <mesh filename="package://c_crane_description/meshes/lower.stl"/>
      </geometry>
    </collision>
    <inertial>
      <inertia ixx="8" ixy="0.18" ixz="0.01" iyy="8" iyz="0.01" izz="16"/>
      <origin rpy="0 0 0" xyz="-0.124 0.001 -0.65"/>
      <geometry>
        <mesh filename="package://c_crane_description/meshes/lower.stl"/>
      </geometry>
      <mass value="1"/>
    </inertial>
  </link>
  <joint name="body_joint" type="fixed">
    <origin rpy="0 0 0" xyz="0 0 1.4"/>
    <parent link="base_link"/>
    <child link="lower_link"/>
  </joint>
  <!-- upper link -->
  <link name="upper_link">
    <visual>
      <origin rpy="0 0 0" xyz="0 0 0"/>
      <geometry>
        <mesh filename="package://c_crane_description/meshes/upper.stl"/>
      </geometry>
    </visual>
    <collision>
      <origin rpy="0 0 0" xyz="0 0 0"/>
      <geometry>
        <mesh filename="package://c_crane_description/meshes/upper.stl"/>
      </geometry>
    </collision>
    <inertial>
      <inertia ixx="12" ixy="0.16" ixz="0.7" iyy="14" iyz="0.1" izz="17"/>
      <origin rpy="0 0 0" xyz="-2.887 -0.042, 1.010"/>
      <geometry>
        <mesh filename="package://c_crane_description/meshes/upper.stl"/>
      </geometry>
      <mass value="1"/>
    </inertial>
  </link>
  <joint name="yaw_joint" type="revolute">
    <origin rpy="0 0 0" xyz="0 0 0"/>
    <parent link="lower_link"/>
    <child link="upper_link"/>
    <axis xyz="0 0 1"/>
    <limit effort="1000000" lower="-1.57" upper="1.57" velocity="10000"/>
  </joint>
  <transmission name="yaw_joint_trans">
    <type>transimission_interface/SimpleTransmission</type>
    <joint name="yaw_joint">
      <hardwareInterface>hardware_interface/VelocityJointInterface</hardwareInterface>
    </joint>
    <actuator name="yaw_joint_motor">
      <hardwareInterface>hardware_interface/VelocityJointInterface</hardwareInterface>
      <mechanicalReduction>1</mechanicalReduction>
    </actuator>
  </transmission>
  <link name="boom_link">
    <visual>
      <geometry>
        <mesh filename="package://c_crane_description/meshes/boom.stl"/>
      </geometry>
      <origin rpy="0 0 0" xyz="-1.1 0 -0.87"/>
    </visual>
    <collision>
      <geometry>
        <mesh filename="package://c_crane_description/meshes/boom.stl"/>
      </geometry>
      <origin rpy="0 0 0" xyz="-1.1 0 -0.87"/>
    </collision>
    <inertial>
      <inertia ixx="55" ixy="0" ixz="32" iyy="74" iyz="0" izz="20"/>
      <!--origin xyz="-1.1 0 -0.87" rpy="0 0 0"/-->
      <origin rpy="0 1.047 0" xyz="8.8153 0.1832 14.276"/>
      <geometry>
        <mesh filename="package://c_crane_description/meshes/boom.stl"/>
      </geometry>
      <mass value="1"/>
    </inertial>
  </link>
  <joint name="pitch_joint" type="revolute">
    <origin rpy="0 0 0" xyz="1.1 0 0.87"/>
    <parent link="upper_link"/>
    <child link="boom_link"/>
    <axis xyz="0 1 0"/>
    <limit effort="100000000" lower="-1" upper="1" velocity="10000"/>
  </joint>
  <transmission name="pitch_joint_trans">
    <type>transimission_interface/SimpleTransmission</type>
    <joint name="pitch_joint">
      <hardwareInterface>hardware_interface/VelocityJointInterface</hardwareInterface>
    </joint>
    <actuator name="pitch_joint_motor">
      <hardwareInterface>hardware_interface/VelocityJointInterface</hardwareInterface>
      <mechanicalReduction>1</mechanicalReduction>
    </actuator>
  </transmission>
</robot>

