<?xml version="1.0" encoding="utf-8"?>
<!-- =================================================================================== -->
<!-- |    This document was autogenerated by xacro from payload.urdf.xacro             | -->
<!-- |    EDITING THIS FILE BY HAND IS NOT RECOMMENDED                                 | -->
<!-- =================================================================================== -->
<robot name="c_crane" xmlns:xacro="http://www.ros.org/wiki/xacro">
  <link name="rope1_link">
    <origin rpy="0 1.57079632679 0" xyz="0 0 0"/>
    <inertial>
      <origin rpy="0 1.57079632679 0" xyz="0 0 0"/>
      <geometry>
        <cylinder length="0.1" radius="0.05"/>
      </geometry>
      <mass value="0.1"/>
      <inertia ixx="0.001" ixy="0.001" ixz="0.001" iyy="0.001" iyz="0.001" izz="0.001"/>
    </inertial>
    <visual>
      <origin rpy="0 1.57079632679 0" xyz="0 0 0"/>
      <geometry>
        <cylinder length="0.1" radius="0.05"/>
      </geometry>
    </visual>
    <collision>
      <origin rpy="0 1.57079632679 0" xyz="0 0 0"/>
      <geometry>
        <cylinder length="0.1" radius="0.05"/>
      </geometry>
    </collision>
  </link>
  <link name="rope2_link">
    <origin rpy="$0 0 0" xyz="0 0 0"/>
    <inertial>
      <origin rpy="1.57079632679 0 0" xyz="0 0 0"/>
      <geometry>
        <cylinder length="0.1" radius="0.05"/>
      </geometry>
      <mass value="0.1"/>
      <inertia ixx="0.001" ixy="0.001" ixz="0.001" iyy="0.001" iyz="0.001" izz="0.001"/>
    </inertial>
    <visual>
      <origin rpy="1.57079632679 0 0" xyz="0 0 0"/>
      <geometry>
        <cylinder length="0.1" radius="0.05"/>
      </geometry>
    </visual>
    <collision>
      <origin rpy="1.57079632679 0 0" xyz="0 0 0"/>
      <geometry>
        <cylinder length="0.1" radius="0.05"/>
      </geometry>
    </collision>
  </link>
  <joint name="joint12" type="continuous">
    <parent link="rope1_link"/>
    <child link="rope2_link"/>
    <origin rpy="0 0 0" xyz="0 0 0"/>
    <axis xyz="0 1 0"/>
    <dynamics friction="10"/>
  </joint>
  <link name="rope3_link">
    <origin rpy="0 0 0" xyz="0 0 0"/>
    <inertial>
      <geometry>
        <cylinder length="0.1" radius="0.05"/>
      </geometry>
      <mass value="0.1"/>
      <inertia ixx="0.001" ixy="0.001" ixz="0.001" iyy="0.001" iyz="0.001" izz="0.001"/>
    </inertial>
    <visual>
      <geometry>
        <cylinder length="0.1" radius="0.05"/>
      </geometry>
    </visual>
    <collision>
      <geometry>
        <cylinder length="0.1" radius="0.05"/>
      </geometry>
    </collision>
  </link>
  <joint name="joint23" type="continuous">
    <parent link="rope2_link"/>
    <child link="rope3_link"/>
    <dynamics friction="10"/>
    <origin rpy="0 0 0" xyz="0 0 0"/>
    <axis xyz="0 0 1"/>
  </joint>
  <link name="rope4_link">
    <origin rpy="0 0 0" xyz="0 0 0"/>
    <inertial>
      <geometry>
        <cylinder length="27" radius="0.05"/>
      </geometry>
      <mass value="0.1"/>
      <inertia ixx="0.001" ixy="0.001" ixz="0.001" iyy="0.001" iyz="0.001" izz="0.001"/>
    </inertial>
    <visual>
      <geometry>
        <cylinder length="27" radius="0.05"/>
      </geometry>
    </visual>
    <collision>
      <geometry>
        <cylinder length="27" radius="0.05"/>
      </geometry>
    </collision>
  </link>
  <joint name="joint34" type="fixed">
    <parent link="rope3_link"/>
    <child link="rope4_link"/>
    <!--origin xyz="0 0 -28" rpy="0 0 0"/-->
    <origin rpy="0 0 0" xyz="0 0 -0.05"/>
    <limit effort="0" lower="-1.57079632679" upper="1.57079632679" velocity="100"/>
  </joint>
  <link name="payload_link">
    <origin rpy="0 0 0" xyz="0 0 0"/>
    <inertial>
      <geometry>
        <box size="1 1 1"/>
      </geometry>
      <mass value="100"/>
      <inertia ixx="0.001" ixy="0.001" ixz="0.001" iyy="0.001" iyz="0.001" izz="0.001"/>
    </inertial>
    <visual>
      <geometry>
        <box size="1 1 1"/>
      </geometry>
    </visual>
    <collision>
      <geometry>
        <box size="1 1 1"/>
      </geometry>
    </collision>
  </link>
  <joint name="joint4payload" type="fixed">
    <parent link="rope4_link"/>
    <child link="payload_link"/>
    <origin rpy="0 0 0" xyz="0 0 -14"/>
  </joint>
</robot>

