<?xml version="1.0"?>
<robot name="k_crane" xmlns:xacro="http://www.ros.org/wiki/xacro">

	<xacro:include filename="k_crane.urdf.xacro"/>
	<xacro:include filename="fixed_payload.urdf.xacro"/>

	<joint name="payload_joint" type="revolute">
		<parent link="boom_link"/>
		<child  link="payload_rope_link"/>
		<origin xyz="31.5 0 -0.5" rpy="0 ${pi/-2} 0"/>
		<axis xyz="1 0 0"/>
		<limit lower="-1.57" upper="1.57" effort="10000" velocity="10"/>
	</joint>
	<xacro:default_transmission suffix="payload_joint"/>
</robot>


