<?xml version="1.0" encoding="utf-8"?>
<!-- =================================================================================== -->
<!-- |    This document was autogenerated by xacro from k_crane_with_payload.urdf.xacro | -->
<!-- |    EDITING THIS FILE BY HAND IS NOT RECOMMENDED                                 | -->
<!-- =================================================================================== -->
<robot name="k_crane">
  <!-- color of robot. important-->
  <material name="white">
    <color rgba="1 1 1 1"/>
  </material>
  <material name="blue">
    <color rgba="0 0 1 1"/>
  </material>
  <material name="red">
    <color rgba="1 0 0 1"/>
  </material>
  <material name="green">
    <color rgba="0 1 0 1"/>
  </material>
  <gazebo>
    <plugin filename="libgazebo_ros_control.so" name="gazebo_ros_control">
      <robotNamespace>/k_crane</robotNamespace>
      <robotSimType>gazebo_ros_control/DefaultRobotHWSim</robotSimType>
    </plugin>
  </gazebo>
  <!-- base_link -->
  <link name="base_link"/>
  <!-- lower link -->
  <link name="lower_link">
    <visual>
      <origin rpy="0 0 0" xyz="0 0 0"/>
      <geometry>
        <mesh filename="package://k_crane_description/meshes/lower.stl"/>
      </geometry>
    </visual>
    <collision>
      <origin rpy="0 0 0" xyz="0 0 0"/>
      <geometry>
        <mesh filename="package://k_crane_description/meshes/lower.stl"/>
      </geometry>
    </collision>
    <inertial>
      <inertia ixx="23141.64" ixy="0.54" ixz="4395.71" iyy="24360.18" iyz="5.63" izz="1218.63"/>
      <origin rpy="0 0 0" xyz="-0.1346 0.0 -0.7573"/>
      <geometry>
        <mesh filename="package://k_crane_description/meshes/lower.stl"/>
      </geometry>
      <mass value="38882"/>
    </inertial>
  </link>
  <joint name="body_joint" type="fixed">
    <origin rpy="0 0 0" xyz="0 0 1.5"/>
    <parent link="base_link"/>
    <child link="lower_link"/>
  </joint>
  <!-- upper link -->
  <link name="upper_link">
    <visual>
      <origin rpy="0 0 0" xyz="0 0 0"/>
      <geometry>
        <mesh filename="package://k_crane_description/meshes/upper.stl"/>
      </geometry>
    </visual>
    <collision>
      <origin rpy="0 0 0" xyz="0 0 0"/>
      <geometry>
        <mesh filename="package://k_crane_description/meshes/upper.stl"/>
      </geometry>
    </collision>
    <inertial>
      <inertia ixx="101881.52" ixy="-50965.14" ixz="-273528.32" iyy="1007600.56" iyz="12056.92" izz="910589.22"/>
      <origin rpy="0 0 0" xyz="-3.1369 0.1401 1.1322"/>
      <geometry>
        <mesh filename="package://k_crane_description/meshes/upper.stl"/>
      </geometry>
      <mass value="77333"/>
    </inertial>
  </link>
  <joint name="yaw_joint" type="revolute">
    <origin rpy="0 0 0" xyz="0 0 0"/>
    <parent link="lower_link"/>
    <child link="upper_link"/>
    <axis xyz="0 0 -1"/>
    <friction frinction="0.05"/>
    <limit effort="100000000" lower="-3.14159265359" upper="3.14159265359" velocity="10000"/>
  </joint>
  <transmission name="yaw_joint_trans">
    <type>transimission_interface/SimpleTransmission</type>
    <joint name="yaw_joint">
      <hardwareInterface>hardware_interface/VelocityJointInterface</hardwareInterface>
    </joint>
    <actuator name="yaw_joint_motor">
      <hardwareInterface>hardware_interface/VelocityJointInterface</hardwareInterface>
      <mechanicalReduction>100</mechanicalReduction>
    </actuator>
  </transmission>
  <link name="boom_link">
    <visual>
      <geometry>
        <mesh filename="package://k_crane_description/meshes/boom.stl"/>
      </geometry>
      <!--origin xyz="-1.4 -0.191 -1.008 " rpy="0 0 0"/-->
      <origin rpy="0 0 -1.57" xyz="0 0 0"/>
    </visual>
    <collision>
      <geometry>
        <mesh filename="package://k_crane_description/meshes/boom.stl"/>
      </geometry>
      <!--origin xyz="-1.4 -0.191 -1.008 " rpy="0 0 0"/-->
      <origin rpy="0 0 -1.57" xyz="0 0 0"/>
    </collision>
    <inertial>
      <inertia ixx="3398809.65" ixy="-2996.64" ixz="18.45" iyy="7038.42" iyz="8974.74" izz="3398634.48"/>
      <origin rpy="0 0 0" xyz="0 0 0"/>
      <geometry>
        <mesh filename="package://k_crane_description/meshes/boom.stl"/>
      </geometry>
      <mass value="8243"/>
    </inertial>
  </link>
  <joint name="pitch_joint" type="revolute">
    <origin rpy="0 0 0" xyz="1.4 0.191 1.008 "/>
    <parent link="upper_link"/>
    <child link="boom_link"/>
    <axis xyz="0 -1 0"/>
    <friction frinction="0.05"/>
    <limit effort="100000000" lower="0" upper="1.57" velocity="10000"/>
  </joint>
  <transmission name="pitch_joint_trans">
    <type>transimission_interface/SimpleTransmission</type>
    <joint name="pitch_joint">
      <hardwareInterface>hardware_interface/VelocityJointInterface</hardwareInterface>
    </joint>
    <actuator name="pitch_joint_motor">
      <hardwareInterface>hardware_interface/VelocityJointInterface</hardwareInterface>
      <mechanicalReduction>100</mechanicalReduction>
    </actuator>
  </transmission>
  <!-- link fixed in order to stand rigidly in gazebo -->
  <link name="world"/>
  <joint name="fixed" type="fixed">
    <parent link="world"/>
    <child link="base_link"/>
    <origin rpy="0 0 0" xyz="0 0 0"/>
  </joint>
  <link name="rope1_link">
    <origin rpy="0 1.57079632679 0" xyz="0 0 0"/>
    <inertial>
      <origin rpy="0 1.57079632679 0" xyz="0 0 0"/>
      <geometry>
        <cylinder length="0.1" radius="0.05"/>
      </geometry>
      <mass value="0.1"/>
      <inertia ixx="0.001" ixy="0.001" ixz="0.001" iyy="0.001" iyz="0.001" izz="0.001"/>
    </inertial>
    <visual>
      <origin rpy="0 1.57079632679 0" xyz="0 0 0"/>
      <geometry>
        <cylinder length="0.1" radius="0.05"/>
      </geometry>
    </visual>
    <collision>
      <origin rpy="0 1.57079632679 0" xyz="0 0 0"/>
      <geometry>
        <cylinder length="0.1" radius="0.05"/>
      </geometry>
    </collision>
  </link>
  <link name="rope2_link">
    <origin rpy="$0 0 0" xyz="0 0 0"/>
    <inertial>
      <origin rpy="1.57079632679 0 0" xyz="0 0 0"/>
      <geometry>
        <cylinder length="0.1" radius="0.05"/>
      </geometry>
      <mass value="0.1"/>
      <inertia ixx="0.001" ixy="0.001" ixz="0.001" iyy="0.001" iyz="0.001" izz="0.001"/>
    </inertial>
    <visual>
      <origin rpy="1.57079632679 0 0" xyz="0 0 0"/>
      <geometry>
        <cylinder length="0.1" radius="0.05"/>
      </geometry>
    </visual>
    <collision>
      <origin rpy="1.57079632679 0 0" xyz="0 0 0"/>
      <geometry>
        <cylinder length="0.1" radius="0.05"/>
      </geometry>
    </collision>
  </link>
  <joint name="joint12" type="continuous">
    <parent link="rope1_link"/>
    <child link="rope2_link"/>
    <origin rpy="0 0 0" xyz="0 0 0"/>
    <axis xyz="0 1 0"/>
    <dynamics friction="10"/>
  </joint>
  <link name="rope3_link">
    <origin rpy="0 0 0" xyz="0 0 0"/>
    <inertial>
      <geometry>
        <cylinder length="0.1" radius="0.05"/>
      </geometry>
      <mass value="0.1"/>
      <inertia ixx="0.001" ixy="0.001" ixz="0.001" iyy="0.001" iyz="0.001" izz="0.001"/>
    </inertial>
    <visual>
      <geometry>
        <cylinder length="0.1" radius="0.05"/>
      </geometry>
    </visual>
    <collision>
      <geometry>
        <cylinder length="0.1" radius="0.05"/>
      </geometry>
    </collision>
  </link>
  <joint name="joint23" type="continuous">
    <parent link="rope2_link"/>
    <child link="rope3_link"/>
    <dynamics friction="10"/>
    <origin rpy="0 0 0" xyz="0 0 0"/>
    <axis xyz="0 0 1"/>
  </joint>
  <link name="rope4_link">
    <origin rpy="0 0 0" xyz="0 0 -14"/>
    <inertial>
      <geometry>
        <cylinder length="27" radius="0.05"/>
      </geometry>
      <mass value="0.1"/>
      <inertia ixx="0.001" ixy="0.001" ixz="0.001" iyy="0.001" iyz="0.001" izz="0.001"/>
    </inertial>
    <visual>
      <geometry>
        <cylinder length="27" radius="0.05"/>
      </geometry>
    </visual>
    <collision>
      <geometry>
        <cylinder length="27" radius="0.05"/>
      </geometry>
    </collision>
  </link>
  <joint name="joint34" type="fixed">
    <parent link="rope3_link"/>
    <child link="rope4_link"/>
    <!--origin xyz="0 0 -28" rpy="0 0 0"/-->
    <origin rpy="0 0 0" xyz="0 0 -14"/>
    <limit effort="0" lower="-1.57079632679" upper="1.57079632679" velocity="100"/>
  </joint>
  <link name="payload_link">
    <origin rpy="0 0 0" xyz="0 0 0"/>
    <inertial>
      <geometry>
        <box size="1 1 1"/>
      </geometry>
      <mass value="100"/>
      <inertia ixx="0.001" ixy="0.001" ixz="0.001" iyy="0.001" iyz="0.001" izz="0.001"/>
    </inertial>
    <visual>
      <geometry>
        <box size="1 1 1"/>
      </geometry>
    </visual>
    <collision>
      <geometry>
        <box size="1 1 1"/>
      </geometry>
    </collision>
  </link>
  <joint name="joint4payload" type="fixed">
    <parent link="rope4_link"/>
    <child link="payload_link"/>
    <origin rpy="0 0 0" xyz="0 0 -13.5"/>
  </joint>
  <joint name="joint_boom1" type="continuous">
    <parent link="boom_link"/>
    <child link="rope1_link"/>
    <origin rpy="0 -1.57079632679 0" xyz="31.5 0 -0.5"/>
    <axis xyz="1 0 0"/>
    <dynamics friction="10"/>
  </joint>
  <joint name="front_camera_joint" type="fixed">
    <parent link="upper_link"/>
    <child link="front_camera_link"/>
    <origin rpy="-1.57079632679 0 -1.57079632679" xyz="2.563 -1.036 0.329"/>
  </joint>
  <link name="front_camera_link"/>
  <gazebo reference="front_camera_link">
    <sensor name="front_camera" type="camera">
      <update_rate>10.0</update_rate>
      <camera name="front_camera">
        <pose>0 0 0 0 -1.57079632679 1.57079632679</pose>
        <horizontal_fov>1.3962634</horizontal_fov>
        <image>
          <width>800</width>
          <height>600</height>
          <format>R8G8B8</format>
        </image>
        <clip>
          <near>0.02</near>
          <far>300</far>
        </clip>
        <noise>
          <type>gaussian</type>
          <mean>0.0</mean>
          <stddev>0.007</stddev>
        </noise>
      </camera>
      <plugin filename="libgazebo_ros_camera.so" name="camera_controller">
        <alwaysOn>true</alwaysOn>
        <updateRate>0.0</updateRate>
        <cameraName>front_camera</cameraName>
        <imageTopicName>image_raw</imageTopicName>
        <cameraInfoTopicName>camera_info</cameraInfoTopicName>
        <frameName>front_camera_link</frameName>
        <hackBaseline>0.0</hackBaseline>
        <distortionK1>0.0</distortionK1>
        <distortionK2>0.0</distortionK2>
        <distortionK3>0.0</distortionK3>
        <distortionT1>0.0</distortionT1>
        <distortionT2>0.0</distortionT2>
      </plugin>
    </sensor>
  </gazebo>
  <link name="camera_link">
    <origin rpy="0 0 0" xyz="0 0 0"/>
    <visual>
      <geometry>
        <box size="0.3 0.1 0.1"/>
      </geometry>
    </visual>
  </link>
  <gazebo reference="camera_link">
    <material>Gazebo/Orange</material>
  </gazebo>
  <joint name="camera_joint" type="fixed">
    <parent link="upper_link"/>
    <child link="camera_link"/>
    <origin rpy="0 0 0" xyz="2.563 -1.036 0.329"/>
  </joint>
</robot>

